22-Dec-19 00:51:31 - root - INFO - MONGO:Tratando de conectar con la base de datos.
22-Dec-19 00:51:32 - root - INFO - MONGO:Conexión completada con éxito.
22-Dec-19 00:51:45 - ecochallenge - ERROR - Exception on /desafios [GET]
Traceback (most recent call last):
  File "/home/rockdrigo/eco-challenge/venv/lib/python3.7/site-packages/flask/app.py", line 1949, in full_dispatch_request
    rv = self.dispatch_request()
  File "/home/rockdrigo/eco-challenge/venv/lib/python3.7/site-packages/flask/app.py", line 1935, in dispatch_request
    return self.view_functions[rule.endpoint](**req.view_args)
  File "/home/rockdrigo/eco-challenge/venv/lib/python3.7/site-packages/flask_restful/__init__.py", line 458, in wrapper
    resp = resource(*args, **kwargs)
  File "/home/rockdrigo/eco-challenge/venv/lib/python3.7/site-packages/flask/views.py", line 89, in view
    return self.dispatch_request(*args, **kwargs)
  File "/home/rockdrigo/eco-challenge/venv/lib/python3.7/site-packages/flask_restful/__init__.py", line 573, in dispatch_request
    resp = meth(*args, **kwargs)
  File "/home/rockdrigo/eco-challenge/principal.py", line 70, in get
    return mongo.getDesafios()
  File "/home/rockdrigo/eco-challenge/mongoDB.py", line 56, in getDesafios
    for j in self.desafio.find():
  File "/home/rockdrigo/eco-challenge/venv/lib/python3.7/site-packages/pymongo/cursor.py", line 1156, in next
    if len(self.__data) or self._refresh():
  File "/home/rockdrigo/eco-challenge/venv/lib/python3.7/site-packages/pymongo/cursor.py", line 1073, in _refresh
    self.__send_message(q)
  File "/home/rockdrigo/eco-challenge/venv/lib/python3.7/site-packages/pymongo/cursor.py", line 955, in __send_message
    address=self.__address)
  File "/home/rockdrigo/eco-challenge/venv/lib/python3.7/site-packages/pymongo/mongo_client.py", line 1347, in _run_operation_with_response
    exhaust=exhaust)
  File "/home/rockdrigo/eco-challenge/venv/lib/python3.7/site-packages/pymongo/mongo_client.py", line 1459, in _retryable_read
    exhaust=exhaust) as (sock_info,
  File "/usr/lib/python3.7/contextlib.py", line 112, in __enter__
    return next(self.gen)
  File "/home/rockdrigo/eco-challenge/venv/lib/python3.7/site-packages/pymongo/mongo_client.py", line 1283, in _slaveok_for_server
    with self._get_socket(server, session, exhaust=exhaust) as sock_info:
  File "/usr/lib/python3.7/contextlib.py", line 112, in __enter__
    return next(self.gen)
  File "/home/rockdrigo/eco-challenge/venv/lib/python3.7/site-packages/pymongo/mongo_client.py", line 1223, in _get_socket
    self.__all_credentials, checkout=exhaust) as sock_info:
  File "/usr/lib/python3.7/contextlib.py", line 112, in __enter__
    return next(self.gen)
  File "/home/rockdrigo/eco-challenge/venv/lib/python3.7/site-packages/pymongo/pool.py", line 1128, in get_socket
    sock_info.check_auth(all_credentials)
  File "/home/rockdrigo/eco-challenge/venv/lib/python3.7/site-packages/pymongo/pool.py", line 712, in check_auth
    auth.authenticate(credentials, self)
  File "/home/rockdrigo/eco-challenge/venv/lib/python3.7/site-packages/pymongo/auth.py", line 564, in authenticate
    auth_func(credentials, sock_info)
  File "/home/rockdrigo/eco-challenge/venv/lib/python3.7/site-packages/pymongo/auth.py", line 539, in _authenticate_default
    return _authenticate_scram(credentials, sock_info, 'SCRAM-SHA-1')
  File "/home/rockdrigo/eco-challenge/venv/lib/python3.7/site-packages/pymongo/auth.py", line 263, in _authenticate_scram
    res = sock_info.command(source, cmd)
  File "/home/rockdrigo/eco-challenge/venv/lib/python3.7/site-packages/pymongo/pool.py", line 613, in command
    user_fields=user_fields)
  File "/home/rockdrigo/eco-challenge/venv/lib/python3.7/site-packages/pymongo/network.py", line 167, in command
    parse_write_concern_error=parse_write_concern_error)
  File "/home/rockdrigo/eco-challenge/venv/lib/python3.7/site-packages/pymongo/helpers.py", line 159, in _check_command_response
    raise OperationFailure(msg % errmsg, code, response)
pymongo.errors.OperationFailure: Authentication failed.
22-Dec-19 00:59:05 - root - INFO - MONGO:Tratando de conectar con la base de datos.
22-Dec-19 00:59:06 - root - INFO - MONGO:Conexión completada con éxito.
22-Dec-19 00:59:15 - ecochallenge - ERROR - Exception on /desafios [GET]
Traceback (most recent call last):
  File "/home/rockdrigo/eco-challenge/venv/lib/python3.7/site-packages/flask/app.py", line 1949, in full_dispatch_request
    rv = self.dispatch_request()
  File "/home/rockdrigo/eco-challenge/venv/lib/python3.7/site-packages/flask/app.py", line 1935, in dispatch_request
    return self.view_functions[rule.endpoint](**req.view_args)
  File "/home/rockdrigo/eco-challenge/venv/lib/python3.7/site-packages/flask_restful/__init__.py", line 458, in wrapper
    resp = resource(*args, **kwargs)
  File "/home/rockdrigo/eco-challenge/venv/lib/python3.7/site-packages/flask/views.py", line 89, in view
    return self.dispatch_request(*args, **kwargs)
  File "/home/rockdrigo/eco-challenge/venv/lib/python3.7/site-packages/flask_restful/__init__.py", line 573, in dispatch_request
    resp = meth(*args, **kwargs)
  File "/home/rockdrigo/eco-challenge/principal.py", line 70, in get
    return mongo.getDesafios()
  File "/home/rockdrigo/eco-challenge/mongoDB.py", line 56, in getDesafios
    for j in self.desafio.find():
  File "/home/rockdrigo/eco-challenge/venv/lib/python3.7/site-packages/pymongo/cursor.py", line 1156, in next
    if len(self.__data) or self._refresh():
  File "/home/rockdrigo/eco-challenge/venv/lib/python3.7/site-packages/pymongo/cursor.py", line 1073, in _refresh
    self.__send_message(q)
  File "/home/rockdrigo/eco-challenge/venv/lib/python3.7/site-packages/pymongo/cursor.py", line 955, in __send_message
    address=self.__address)
  File "/home/rockdrigo/eco-challenge/venv/lib/python3.7/site-packages/pymongo/mongo_client.py", line 1347, in _run_operation_with_response
    exhaust=exhaust)
  File "/home/rockdrigo/eco-challenge/venv/lib/python3.7/site-packages/pymongo/mongo_client.py", line 1459, in _retryable_read
    exhaust=exhaust) as (sock_info,
  File "/usr/lib/python3.7/contextlib.py", line 112, in __enter__
    return next(self.gen)
  File "/home/rockdrigo/eco-challenge/venv/lib/python3.7/site-packages/pymongo/mongo_client.py", line 1283, in _slaveok_for_server
    with self._get_socket(server, session, exhaust=exhaust) as sock_info:
  File "/usr/lib/python3.7/contextlib.py", line 112, in __enter__
    return next(self.gen)
  File "/home/rockdrigo/eco-challenge/venv/lib/python3.7/site-packages/pymongo/mongo_client.py", line 1223, in _get_socket
    self.__all_credentials, checkout=exhaust) as sock_info:
  File "/usr/lib/python3.7/contextlib.py", line 112, in __enter__
    return next(self.gen)
  File "/home/rockdrigo/eco-challenge/venv/lib/python3.7/site-packages/pymongo/pool.py", line 1128, in get_socket
    sock_info.check_auth(all_credentials)
  File "/home/rockdrigo/eco-challenge/venv/lib/python3.7/site-packages/pymongo/pool.py", line 712, in check_auth
    auth.authenticate(credentials, self)
  File "/home/rockdrigo/eco-challenge/venv/lib/python3.7/site-packages/pymongo/auth.py", line 564, in authenticate
    auth_func(credentials, sock_info)
  File "/home/rockdrigo/eco-challenge/venv/lib/python3.7/site-packages/pymongo/auth.py", line 539, in _authenticate_default
    return _authenticate_scram(credentials, sock_info, 'SCRAM-SHA-1')
  File "/home/rockdrigo/eco-challenge/venv/lib/python3.7/site-packages/pymongo/auth.py", line 263, in _authenticate_scram
    res = sock_info.command(source, cmd)
  File "/home/rockdrigo/eco-challenge/venv/lib/python3.7/site-packages/pymongo/pool.py", line 613, in command
    user_fields=user_fields)
  File "/home/rockdrigo/eco-challenge/venv/lib/python3.7/site-packages/pymongo/network.py", line 167, in command
    parse_write_concern_error=parse_write_concern_error)
  File "/home/rockdrigo/eco-challenge/venv/lib/python3.7/site-packages/pymongo/helpers.py", line 159, in _check_command_response
    raise OperationFailure(msg % errmsg, code, response)
pymongo.errors.OperationFailure: Authentication failed.
22-Dec-19 01:06:19 - root - INFO - MONGO:Tratando de conectar con la base de datos.
22-Dec-19 01:06:19 - root - INFO - MONGO:Conexión completada con éxito.
22-Dec-19 01:06:19 - root - INFO - MONGO:Desafio Reciclaje insertado en la base de datos.
22-Dec-19 01:06:19 - root - INFO - MONGO:Desafio Bike insertado en la base de datos.
22-Dec-19 01:06:19 - root - INFO - MONGO:Desafio Limpia insertado en la base de datos.
22-Dec-19 01:06:28 - root - INFO - MONGO:Tratando de conectar con la base de datos.
22-Dec-19 01:06:29 - root - INFO - MONGO:Conexión completada con éxito.
22-Dec-19 01:06:46 - ecochallenge - ERROR - Exception on /desafios [GET]
Traceback (most recent call last):
  File "/home/rockdrigo/eco-challenge/venv/lib/python3.7/site-packages/flask/app.py", line 1949, in full_dispatch_request
    rv = self.dispatch_request()
  File "/home/rockdrigo/eco-challenge/venv/lib/python3.7/site-packages/flask/app.py", line 1935, in dispatch_request
    return self.view_functions[rule.endpoint](**req.view_args)
  File "/home/rockdrigo/eco-challenge/venv/lib/python3.7/site-packages/flask_restful/__init__.py", line 458, in wrapper
    resp = resource(*args, **kwargs)
  File "/home/rockdrigo/eco-challenge/venv/lib/python3.7/site-packages/flask/views.py", line 89, in view
    return self.dispatch_request(*args, **kwargs)
  File "/home/rockdrigo/eco-challenge/venv/lib/python3.7/site-packages/flask_restful/__init__.py", line 573, in dispatch_request
    resp = meth(*args, **kwargs)
  File "/home/rockdrigo/eco-challenge/principal.py", line 70, in get
    return mongo.getDesafios()
  File "/home/rockdrigo/eco-challenge/mongoDB.py", line 56, in getDesafios
    for j in self.desafio.find():
  File "/home/rockdrigo/eco-challenge/venv/lib/python3.7/site-packages/pymongo/cursor.py", line 1156, in next
    if len(self.__data) or self._refresh():
  File "/home/rockdrigo/eco-challenge/venv/lib/python3.7/site-packages/pymongo/cursor.py", line 1073, in _refresh
    self.__send_message(q)
  File "/home/rockdrigo/eco-challenge/venv/lib/python3.7/site-packages/pymongo/cursor.py", line 955, in __send_message
    address=self.__address)
  File "/home/rockdrigo/eco-challenge/venv/lib/python3.7/site-packages/pymongo/mongo_client.py", line 1347, in _run_operation_with_response
    exhaust=exhaust)
  File "/home/rockdrigo/eco-challenge/venv/lib/python3.7/site-packages/pymongo/mongo_client.py", line 1459, in _retryable_read
    exhaust=exhaust) as (sock_info,
  File "/usr/lib/python3.7/contextlib.py", line 112, in __enter__
    return next(self.gen)
  File "/home/rockdrigo/eco-challenge/venv/lib/python3.7/site-packages/pymongo/mongo_client.py", line 1283, in _slaveok_for_server
    with self._get_socket(server, session, exhaust=exhaust) as sock_info:
  File "/usr/lib/python3.7/contextlib.py", line 112, in __enter__
    return next(self.gen)
  File "/home/rockdrigo/eco-challenge/venv/lib/python3.7/site-packages/pymongo/mongo_client.py", line 1223, in _get_socket
    self.__all_credentials, checkout=exhaust) as sock_info:
  File "/usr/lib/python3.7/contextlib.py", line 112, in __enter__
    return next(self.gen)
  File "/home/rockdrigo/eco-challenge/venv/lib/python3.7/site-packages/pymongo/pool.py", line 1128, in get_socket
    sock_info.check_auth(all_credentials)
  File "/home/rockdrigo/eco-challenge/venv/lib/python3.7/site-packages/pymongo/pool.py", line 712, in check_auth
    auth.authenticate(credentials, self)
  File "/home/rockdrigo/eco-challenge/venv/lib/python3.7/site-packages/pymongo/auth.py", line 564, in authenticate
    auth_func(credentials, sock_info)
  File "/home/rockdrigo/eco-challenge/venv/lib/python3.7/site-packages/pymongo/auth.py", line 539, in _authenticate_default
    return _authenticate_scram(credentials, sock_info, 'SCRAM-SHA-1')
  File "/home/rockdrigo/eco-challenge/venv/lib/python3.7/site-packages/pymongo/auth.py", line 263, in _authenticate_scram
    res = sock_info.command(source, cmd)
  File "/home/rockdrigo/eco-challenge/venv/lib/python3.7/site-packages/pymongo/pool.py", line 613, in command
    user_fields=user_fields)
  File "/home/rockdrigo/eco-challenge/venv/lib/python3.7/site-packages/pymongo/network.py", line 167, in command
    parse_write_concern_error=parse_write_concern_error)
  File "/home/rockdrigo/eco-challenge/venv/lib/python3.7/site-packages/pymongo/helpers.py", line 159, in _check_command_response
    raise OperationFailure(msg % errmsg, code, response)
pymongo.errors.OperationFailure: Authentication failed.
22-Dec-19 01:10:20 - root - INFO - Obteniendo desafios de la base de datos.
22-Dec-19 01:10:20 - root - INFO - MONGO:Tratando de conectar con la base de datos.
22-Dec-19 01:10:20 - root - INFO - MONGO:Conexión completada con éxito.
22-Dec-19 01:11:10 - ecochallenge - ERROR - Exception on /desafios [GET]
Traceback (most recent call last):
  File "/home/rockdrigo/eco-challenge/venv/lib/python3.7/site-packages/flask/app.py", line 1949, in full_dispatch_request
    rv = self.dispatch_request()
  File "/home/rockdrigo/eco-challenge/venv/lib/python3.7/site-packages/flask/app.py", line 1935, in dispatch_request
    return self.view_functions[rule.endpoint](**req.view_args)
  File "/home/rockdrigo/eco-challenge/venv/lib/python3.7/site-packages/flask_restful/__init__.py", line 458, in wrapper
    resp = resource(*args, **kwargs)
  File "/home/rockdrigo/eco-challenge/venv/lib/python3.7/site-packages/flask/views.py", line 89, in view
    return self.dispatch_request(*args, **kwargs)
  File "/home/rockdrigo/eco-challenge/venv/lib/python3.7/site-packages/flask_restful/__init__.py", line 573, in dispatch_request
    resp = meth(*args, **kwargs)
  File "/home/rockdrigo/eco-challenge/principal.py", line 71, in get
    return mongo.getDesafios()
  File "/home/rockdrigo/eco-challenge/mongoDB.py", line 56, in getDesafios
    for j in self.desafio.find():
  File "/home/rockdrigo/eco-challenge/venv/lib/python3.7/site-packages/pymongo/cursor.py", line 1156, in next
    if len(self.__data) or self._refresh():
  File "/home/rockdrigo/eco-challenge/venv/lib/python3.7/site-packages/pymongo/cursor.py", line 1073, in _refresh
    self.__send_message(q)
  File "/home/rockdrigo/eco-challenge/venv/lib/python3.7/site-packages/pymongo/cursor.py", line 955, in __send_message
    address=self.__address)
  File "/home/rockdrigo/eco-challenge/venv/lib/python3.7/site-packages/pymongo/mongo_client.py", line 1347, in _run_operation_with_response
    exhaust=exhaust)
  File "/home/rockdrigo/eco-challenge/venv/lib/python3.7/site-packages/pymongo/mongo_client.py", line 1459, in _retryable_read
    exhaust=exhaust) as (sock_info,
  File "/usr/lib/python3.7/contextlib.py", line 112, in __enter__
    return next(self.gen)
  File "/home/rockdrigo/eco-challenge/venv/lib/python3.7/site-packages/pymongo/mongo_client.py", line 1283, in _slaveok_for_server
    with self._get_socket(server, session, exhaust=exhaust) as sock_info:
  File "/usr/lib/python3.7/contextlib.py", line 112, in __enter__
    return next(self.gen)
  File "/home/rockdrigo/eco-challenge/venv/lib/python3.7/site-packages/pymongo/mongo_client.py", line 1223, in _get_socket
    self.__all_credentials, checkout=exhaust) as sock_info:
  File "/usr/lib/python3.7/contextlib.py", line 112, in __enter__
    return next(self.gen)
  File "/home/rockdrigo/eco-challenge/venv/lib/python3.7/site-packages/pymongo/pool.py", line 1128, in get_socket
    sock_info.check_auth(all_credentials)
  File "/home/rockdrigo/eco-challenge/venv/lib/python3.7/site-packages/pymongo/pool.py", line 712, in check_auth
    auth.authenticate(credentials, self)
  File "/home/rockdrigo/eco-challenge/venv/lib/python3.7/site-packages/pymongo/auth.py", line 564, in authenticate
    auth_func(credentials, sock_info)
  File "/home/rockdrigo/eco-challenge/venv/lib/python3.7/site-packages/pymongo/auth.py", line 539, in _authenticate_default
    return _authenticate_scram(credentials, sock_info, 'SCRAM-SHA-1')
  File "/home/rockdrigo/eco-challenge/venv/lib/python3.7/site-packages/pymongo/auth.py", line 263, in _authenticate_scram
    res = sock_info.command(source, cmd)
  File "/home/rockdrigo/eco-challenge/venv/lib/python3.7/site-packages/pymongo/pool.py", line 613, in command
    user_fields=user_fields)
  File "/home/rockdrigo/eco-challenge/venv/lib/python3.7/site-packages/pymongo/network.py", line 167, in command
    parse_write_concern_error=parse_write_concern_error)
  File "/home/rockdrigo/eco-challenge/venv/lib/python3.7/site-packages/pymongo/helpers.py", line 159, in _check_command_response
    raise OperationFailure(msg % errmsg, code, response)
pymongo.errors.OperationFailure: Authentication failed.
22-Dec-19 01:11:32 - ecochallenge - ERROR - Exception on /desafios [GET]
Traceback (most recent call last):
  File "/home/rockdrigo/eco-challenge/venv/lib/python3.7/site-packages/flask/app.py", line 1949, in full_dispatch_request
    rv = self.dispatch_request()
  File "/home/rockdrigo/eco-challenge/venv/lib/python3.7/site-packages/flask/app.py", line 1935, in dispatch_request
    return self.view_functions[rule.endpoint](**req.view_args)
  File "/home/rockdrigo/eco-challenge/venv/lib/python3.7/site-packages/flask_restful/__init__.py", line 458, in wrapper
    resp = resource(*args, **kwargs)
  File "/home/rockdrigo/eco-challenge/venv/lib/python3.7/site-packages/flask/views.py", line 89, in view
    return self.dispatch_request(*args, **kwargs)
  File "/home/rockdrigo/eco-challenge/venv/lib/python3.7/site-packages/flask_restful/__init__.py", line 573, in dispatch_request
    resp = meth(*args, **kwargs)
  File "/home/rockdrigo/eco-challenge/principal.py", line 71, in get
    return mongo.getDesafios()
  File "/home/rockdrigo/eco-challenge/mongoDB.py", line 56, in getDesafios
    for j in self.desafio.find():
  File "/home/rockdrigo/eco-challenge/venv/lib/python3.7/site-packages/pymongo/cursor.py", line 1156, in next
    if len(self.__data) or self._refresh():
  File "/home/rockdrigo/eco-challenge/venv/lib/python3.7/site-packages/pymongo/cursor.py", line 1073, in _refresh
    self.__send_message(q)
  File "/home/rockdrigo/eco-challenge/venv/lib/python3.7/site-packages/pymongo/cursor.py", line 955, in __send_message
    address=self.__address)
  File "/home/rockdrigo/eco-challenge/venv/lib/python3.7/site-packages/pymongo/mongo_client.py", line 1347, in _run_operation_with_response
    exhaust=exhaust)
  File "/home/rockdrigo/eco-challenge/venv/lib/python3.7/site-packages/pymongo/mongo_client.py", line 1459, in _retryable_read
    exhaust=exhaust) as (sock_info,
  File "/usr/lib/python3.7/contextlib.py", line 112, in __enter__
    return next(self.gen)
  File "/home/rockdrigo/eco-challenge/venv/lib/python3.7/site-packages/pymongo/mongo_client.py", line 1283, in _slaveok_for_server
    with self._get_socket(server, session, exhaust=exhaust) as sock_info:
  File "/usr/lib/python3.7/contextlib.py", line 112, in __enter__
    return next(self.gen)
  File "/home/rockdrigo/eco-challenge/venv/lib/python3.7/site-packages/pymongo/mongo_client.py", line 1223, in _get_socket
    self.__all_credentials, checkout=exhaust) as sock_info:
  File "/usr/lib/python3.7/contextlib.py", line 112, in __enter__
    return next(self.gen)
  File "/home/rockdrigo/eco-challenge/venv/lib/python3.7/site-packages/pymongo/pool.py", line 1128, in get_socket
    sock_info.check_auth(all_credentials)
  File "/home/rockdrigo/eco-challenge/venv/lib/python3.7/site-packages/pymongo/pool.py", line 712, in check_auth
    auth.authenticate(credentials, self)
  File "/home/rockdrigo/eco-challenge/venv/lib/python3.7/site-packages/pymongo/auth.py", line 564, in authenticate
    auth_func(credentials, sock_info)
  File "/home/rockdrigo/eco-challenge/venv/lib/python3.7/site-packages/pymongo/auth.py", line 539, in _authenticate_default
    return _authenticate_scram(credentials, sock_info, 'SCRAM-SHA-1')
  File "/home/rockdrigo/eco-challenge/venv/lib/python3.7/site-packages/pymongo/auth.py", line 263, in _authenticate_scram
    res = sock_info.command(source, cmd)
  File "/home/rockdrigo/eco-challenge/venv/lib/python3.7/site-packages/pymongo/pool.py", line 613, in command
    user_fields=user_fields)
  File "/home/rockdrigo/eco-challenge/venv/lib/python3.7/site-packages/pymongo/network.py", line 167, in command
    parse_write_concern_error=parse_write_concern_error)
  File "/home/rockdrigo/eco-challenge/venv/lib/python3.7/site-packages/pymongo/helpers.py", line 159, in _check_command_response
    raise OperationFailure(msg % errmsg, code, response)
pymongo.errors.OperationFailure: Authentication failed.
22-Dec-19 01:12:03 - root - INFO - Obteniendo desafios de la base de datos.
22-Dec-19 01:12:03 - root - INFO - MONGO:Tratando de conectar con la base de datos.
22-Dec-19 01:12:03 - root - INFO - MONGO:Conexión completada con éxito.
22-Dec-19 01:16:28 - root - INFO - Obteniendo desafios de la base de datos.
22-Dec-19 01:16:28 - root - INFO - MONGO:Tratando de conectar con la base de datos.
22-Dec-19 01:16:28 - root - INFO - MONGO:Conexión completada con éxito.
22-Dec-19 01:16:35 - root - INFO - MONGO:Todos los Desafios de la base de datos devueltos.
22-Dec-19 01:17:05 - root - INFO - Obteniendo desafios de la base de datos.
22-Dec-19 01:17:05 - root - INFO - MONGO:Tratando de conectar con la base de datos.
22-Dec-19 01:17:05 - root - INFO - MONGO:Conexión completada con éxito.
22-Dec-19 01:17:52 - root - INFO - Obteniendo desafios de la base de datos.
22-Dec-19 01:17:52 - root - INFO - MONGO:Tratando de conectar con la base de datos.
22-Dec-19 01:17:52 - root - INFO - MONGO:Conexión completada con éxito.
22-Dec-19 01:18:02 - root - INFO - MONGO:Todos los Desafios de la base de datos devueltos.
22-Dec-19 01:19:35 - root - INFO - MONGO:Tratando de conectar con la base de datos.
22-Dec-19 01:19:35 - root - INFO - MONGO:Conexión completada con éxito.
22-Dec-19 01:19:35 - root - INFO - MONGO:Desafio Reciclaje2 insertado en la base de datos.
22-Dec-19 01:19:35 - root - INFO - MONGO:Desafio Bike2 insertado en la base de datos.
22-Dec-19 01:19:35 - root - INFO - MONGO:Desafio Limpia2 insertado en la base de datos.
22-Dec-19 01:19:39 - root - INFO - MONGO:Todos los Desafios de la base de datos devueltos.
22-Dec-19 01:19:41 - root - INFO - MONGO:Todos los Desafios de la base de datos devueltos.
22-Dec-19 01:19:42 - root - INFO - MONGO:Todos los Desafios de la base de datos devueltos.
22-Dec-19 01:19:43 - root - INFO - MONGO:Todos los Desafios de la base de datos devueltos.
22-Dec-19 01:20:14 - root - INFO - Obteniendo desafios de la base de datos.
22-Dec-19 01:20:14 - root - INFO - MONGO:Tratando de conectar con la base de datos.
22-Dec-19 01:20:14 - root - INFO - MONGO:Conexión completada con éxito.
22-Dec-19 01:21:14 - root - INFO - MONGO:Todos los Desafios de la base de datos devueltos.
22-Dec-19 01:22:12 - root - INFO - base de datos cloud
22-Dec-19 01:22:12 - root - INFO - MONGO:Tratando de conectar con la base de datos.
22-Dec-19 01:22:13 - root - INFO - MONGO:Conexión completada con éxito.
22-Dec-19 01:23:51 - root - INFO - base de datos cloudNone
22-Dec-19 01:23:51 - root - INFO - MONGO:Tratando de conectar con la base de datos.
22-Dec-19 01:23:51 - root - INFO - MONGO:Conexión completada con éxito.
22-Dec-19 01:24:50 - root - INFO - base de datos cloudNone
22-Dec-19 01:24:50 - root - INFO - MONGO:Tratando de conectar con la base de datos.
22-Dec-19 01:24:50 - root - INFO - MONGO:Conexión completada con éxito.
22-Dec-19 01:25:17 - root - INFO - base de datos local
22-Dec-19 01:25:17 - root - INFO - MONGO:Tratando de conectar con la base de datos.
22-Dec-19 01:25:17 - root - INFO - MONGO:Conexión completada con éxito.
22-Dec-19 01:25:29 - root - INFO - MONGO:Todos los Desafios de la base de datos devueltos.
22-Dec-19 01:26:00 - root - INFO - base de datos local
22-Dec-19 01:26:00 - root - INFO - MONGO:Tratando de conectar con la base de datos.
22-Dec-19 01:26:00 - root - INFO - MONGO:Conexión completada con éxito.
